Workbook

Sheet Dashboard
A1: Trendyol Karar Destek Dashboard
A3: Özet | B3: Değer
A4: Toplam Ürün | B4: =COUNTA(Products!A2:A1000) -> 464
A5: BuyBox Fiyatı Olan Ürün | B5: =COUNTIF(Products!P2:P1000,">0") -> 204
A6: Hesaplanan Ürün | B6: =COUNTIF('BuyBox Karlilik'!M2:M300,"KÂRLI")+COUNTIF('BuyBox Karlilik'!M2:M300,"ZARAR") -> 184
A7: Kârlı Ürün | B7: =COUNTIF('BuyBox Karlilik'!M2:M300,"KÂRLI") -> 126
A8: Zarar Ürün | B8: =COUNTIF('BuyBox Karlilik'!M2:M300,"ZARAR") -> 58
A9: Eksik Veri | B9: =COUNTIF('BuyBox Karlilik'!M2:M300,"EKSİK VERİ") -> 20
A10: Çok Kârlı | B10: =COUNTIF('BuyBox Karlilik'!T2:T300,"ÇOK KÂRLI") -> 39
A11: Sağlıklı | B11: =COUNTIF('BuyBox Karlilik'!T2:T300,"SAĞLIKLI") -> 27
A12: Düşük Kâr | B12: =COUNTIF('BuyBox Karlilik'!T2:T300,"DÜŞÜK KÂR") -> 30
A13: Riskli | B13: =COUNTIF('BuyBox Karlilik'!T2:T300,"RİSKLİ") -> 30
A14: Tekrarlı Barkod | B14: =COUNTIF('Maliyet Giris'!I2:I550,"Tekrarlı barkod") -> 0
A15: Toplam Net Kâr | B15: =SUM('BuyBox Karlilik'!K2:K300) -> 20898.093
A16: Ortalama Kâr Oranı | B16: =IFERROR(__xludf.DUMMYFUNCTION("IFERROR(AVERAGE(FILTER('BuyBox Karlilik'!L2:L300,'BuyBox Karlilik'!L2:L300<>"""")),0)"),0.07656346898719861) -> 0.076563469
A17: En Yüksek Net Kâr | B17: =MAX('BuyBox Karlilik'!K2:K300) -> 3081.925
A18: En Büyük Zarar | B18: =MIN('BuyBox Karlilik'!K2:K300) -> -263.32333
A20: En Kârlı İlk 10 Ürün
A21: Barkod | B21: Marka | C21: Ürün Adı | D21: BuyBox Fiyatı | E21: Komisyon | F21: Kargo | G21: Maliyet | H21: Net Kâr | I21: Kâr Oranı | J21: Risk | K21: Aksiyon
A22: =IFERROR(__xludf.DUMMYFUNCTION("SORTN(FILTER({'BuyBox Karlilik'!A2:G300,'BuyBox Karlilik'!K2:L300,'BuyBox Karlilik'!T2:U300},'BuyBox Karlilik'!M2:M300=""KÂRLI""),10,0,8,FALSE)"),"H22HBCV000075VENA") -> H22HBCV000075VENA | B22: =IFERROR(__xludf.DUMMYFUNCTION("""COMPUTED_VALUE"""),"Orqinel") -> Orqinel | C22: =IFERROR(__xludf.DUMMYFUNCTION("""COMPUTED_VALUE"""),"Virbac Adult Cat Salmon Neutered & Entire 7 kg") -> Virbac Adult Cat Salmon Neutered & Entire 7 kg | D22: =IFERROR(__xludf.DUMMYFUNCTION("""COMPUTED_VALUE"""),4620.0) -> 4620 | E22: =IFERROR(__xludf.DUMMYFUNCTION("""COMPUTED_VALUE"""),762.3) -> 762.3 | F22: =IFERROR(__xludf.DUMMYFUNCTION("""COMPUTED_VALUE"""),90.0) -> 90 | G22: =IFERROR(__xludf.DUMMYFUNCTION("""COMPUTED_VALUE"""),10.0) -> 10 | H22: =IFERROR(__xludf.DUMMYFUNCTION("""COMPUTED_VALUE"""),3081.9249999999997) -> 3081.925 | I22: =IFERROR(__xludf.DUMMYFUNCTION("""COMPUTED_VALUE"""),0.6670833333333333) -> 0.66708333 | J22: =IFERROR(__xludf.DUMMYFUNCTION("""COMPUTED_VALUE"""),"ÇOK KÂRLI") -> ÇOK KÂRLI | K22: =IFERROR(__xludf.DUMMYFUNCTION("""COMPUTED_VALUE"""),"Stok ve BuyBox takibini artır") -> Stok ve BuyBox takibini artır
A23: =IFERROR(__xludf.DUMMYFUNCTION("""COMPUTED_VALUE"""),3.5585356426E10) -> 35585356426 | B23: =IFERROR(__xludf.DUMMYFUNCTION("""COMPUTED_VALUE"""),"Kong") -> Kong | C23: =IFERROR(__xludf.DUMMYFUNCTION("""COMPUTED_VALUE"""),"EXTREMETOP ŞEKLİNDESESLİ VE İPSALLANTILI KÖPEKOYUNCAĞI ULTRASERT L") -> EXTREMETOP ŞEKLİNDESESLİ VE İPSALLANTILI KÖPEKOYUNCAĞI ULTRASERT L | D23: =IFERROR(__xludf.DUMMYFUNCTION("""COMPUTED_VALUE"""),2179.0) -> 2179 | E23: =IFERROR(__xludf.DUMMYFUNCTION("""COMPUTED_VALUE"""),435.8) -> 435.8 | F23: =IFERROR(__xludf.DUMMYFUNCTION("""COMPUTED_VALUE"""),86.4) -> 86.4 | G23: =IFERROR(__xludf.DUMMYFUNCTION("""COMPUTED_VALUE"""),347.76) -> 347.76 | H23: =IFERROR(__xludf.DUMMYFUNCTION("""COMPUTED_VALUE"""),1061.7166666666667) -> 1061.7167 | I23: =IFERROR(__xludf.DUMMYFUNCTION("""COMPUTED_VALUE"""),0.48724950283004437) -> 0.4872495 | J23: =IFERROR(__xludf.DUMMYFUNCTION("""COMPUTED_VALUE"""),"ÇOK KÂRLI") -> ÇOK KÂRLI | K23: =IFERROR(__xludf.DUMMYFUNCTION("""COMPUTED_VALUE"""),"Stok ve BuyBox takibini artır") -> Stok ve BuyBox takibini artır
A24: =IFERROR(__xludf.DUMMYFUNCTION("""COMPUTED_VALUE"""),4.49531020003577E14) -> 449531020003577 | B24: =IFERROR(__xludf.DUMMYFUNCTION("""COMPUTED_VALUE"""),"Royal Canin") -> Royal Canin | C24: =IFERROR(__xludf.DUMMYFUNCTION("""COMPUTED_VALUE"""),"Gravy Ageing +12 Kedi Yaş Mama 85 Gr. X 24 Adet") -> Gravy Ageing +12 Kedi Yaş Mama 85 Gr. X 24 Adet | D24: =IFERROR(__xludf.DUMMYFUNCTION("""COMPUTED_VALUE"""),1799.0) -> 1799 | E24: =IFERROR(__xludf.DUMMYFUNCTION("""COMPUTED_VALUE"""),224.875) -> 224.875 | F24: =IFERROR(__xludf.DUMMYFUNCTION("""COMPUTED_VALUE"""),90.0) -> 90 | G24: =IFERROR(__xludf.DUMMYFUNCTION("""COMPUTED_VALUE"""),465.0) -> 465 | H24: =IFERROR(__xludf.DUMMYFUNCTION("""COMPUTED_VALUE"""),823.2875) -> 823.2875 | I24: =IFERROR(__xludf.DUMMYFUNCTION("""COMPUTED_VALUE"""),0.45763618677042806) -> 0.45763619 | J24: =IFERROR(__xludf.DUMMYFUNCTION("""COMPUTED_VALUE"""),"ÇOK KÂRLI") -> ÇOK KÂRLI | K24: =IFERROR(__xludf.DUMMYFUNCTION("""COMPUTED_VALUE"""),"Stok ve BuyBox takibini artır") -> Stok ve BuyBox takibini artır
A25: =IFERROR(__xludf.DUMMYFUNCTION("""COMPUTED_VALUE"""),8.681002997592E12) -> 8681002997592 | B25: =IFERROR(__xludf.DUMMYFUNCTION("""COMPUTED_VALUE"""),"Dreamies") -> Dreamies | C25: =IFERROR(__xludf.DUMMYFUNCTION("""COMPUTED_VALUE"""),"Kedi Ödül Maması Karışık Paket 60 Gr X 36 Adet") -> Kedi Ödül Maması Karışık Paket 60 Gr X 36 Adet | D25: =IFERROR(__xludf.DUMMYFUNCTION("""COMPUTED_VALUE"""),1455.0) -> 1455 | E25: =IFERROR(__xludf.DUMMYFUNCTION("""COMPUTED_VALUE"""),291.0) -> 291 | F25: =IFERROR(__xludf.DUMMYFUNCTION("""COMPUTED_VALUE"""),86.4) -> 86.4 | G25: =IFERROR(__xludf.DUMMYFUNCTION("""COMPUTED_VALUE"""),100.0) -> 100 | H25: =IFERROR(__xludf.DUMMYFUNCTION("""COMPUTED_VALUE"""),791.5499999999998) -> 791.55 | I25: =IFERROR(__xludf.DUMMYFUNCTION("""COMPUTED_VALUE"""),0.5440206185567009) -> 0.54402062 | J25: =IFERROR(__xludf.DUMMYFUNCTION("""COMPUTED_VALUE"""),"ÇOK KÂRLI") -> ÇOK KÂRLI | K25: =IFERROR(__xludf.DUMMYFUNCTION("""COMPUTED_VALUE"""),"Stok ve BuyBox takibini artır") -> Stok ve BuyBox takibini artır
A26: =IFERROR(__xludf.DUMMYFUNCTION("""COMPUTED_VALUE"""),3.5585356389E10) -> 35585356389 | B26: =IFERROR(__xludf.DUMMYFUNCTION("""COMPUTED_VALUE"""),"Kong") -> Kong | C26: =IFERROR(__xludf.DUMMYFUNCTION("""COMPUTED_VALUE"""),"EXTREMEÇOKLU TOPŞEKLİNDE KÖPEKOYUNCAĞI ULTRASERT L") -> EXTREMEÇOKLU TOPŞEKLİNDE KÖPEKOYUNCAĞI ULTRASERT L | D26: =IFERROR(__xludf.DUMMYFUNCTION("""COMPUTED_VALUE"""),2340.0) -> 2340 | E26: =IFERROR(__xludf.DUMMYFUNCTION("""COMPUTED_VALUE"""),468.0) -> 468 | F26: =IFERROR(__xludf.DUMMYFUNCTION("""COMPUTED_VALUE"""),86.4) -> 86.4 | G26: =IFERROR(__xludf.DUMMYFUNCTION("""COMPUTED_VALUE"""),925.2) -> 925.2 | H26: =IFERROR(__xludf.DUMMYFUNCTION("""COMPUTED_VALUE"""),686.508333333333) -> 686.50833 | I26: =IFERROR(__xludf.DUMMYFUNCTION("""COMPUTED_VALUE"""),0.2933796296296295) -> 0.29337963 | J26: =IFERROR(__xludf.DUMMYFUNCTION("""COMPUTED_VALUE"""),"ÇOK KÂRLI") -> ÇOK KÂRLI | K26: =IFERROR(__xludf.DUMMYFUNCTION("""COMPUTED_VALUE"""),"Stok ve BuyBox takibini artır") -> Stok ve BuyBox takibini artır
A27: =IFERROR(__xludf.DUMMYFUNCTION("""COMPUTED_VALUE"""),3.5585356242E10) -> 35585356242 | B27: =IFERROR(__xludf.DUMMYFUNCTION("""COMPUTED_VALUE"""),"Kong") -> Kong | C27: =IFERROR(__xludf.DUMMYFUNCTION("""COMPUTED_VALUE"""),"GOODİERİBBON ÇOKLUTOP ŞEKLİNDEKÖPEKOYUNCAĞI L") -> GOODİERİBBON ÇOKLUTOP ŞEKLİNDEKÖPEKOYUNCAĞI L | D27: =IFERROR(__xludf.DUMMYFUNCTION("""COMPUTED_VALUE"""),2329.0) -> 2329 | E27: =IFERROR(__xludf.DUMMYFUNCTION("""COMPUTED_VALUE"""),465.8) -> 465.8 | F27: =IFERROR(__xludf.DUMMYFUNCTION("""COMPUTED_VALUE"""),86.4) -> 86.4 | G27: =IFERROR(__xludf.DUMMYFUNCTION("""COMPUTED_VALUE"""),919.44) -> 919.44 | H27: =IFERROR(__xludf.DUMMYFUNCTION("""COMPUTED_VALUE"""),684.0666666666666) -> 684.06667 | I27: =IFERROR(__xludf.DUMMYFUNCTION("""COMPUTED_VALUE"""),0.29371690281952195) -> 0.2937169 | J27: =IFERROR(__xludf.DUMMYFUNCTION("""COMPUTED_VALUE"""),"ÇOK KÂRLI") -> ÇOK KÂRLI | K27: =IFERROR(__xludf.DUMMYFUNCTION("""COMPUTED_VALUE"""),"Stok ve BuyBox takibini artır") -> Stok ve BuyBox takibini artır
A28: =IFERROR(__xludf.DUMMYFUNCTION("""COMPUTED_VALUE"""),6.2420056724154E13) -> 62420056724154 | B28: =IFERROR(__xludf.DUMMYFUNCTION("""COMPUTED_VALUE"""),"Dreamies") -> Dreamies | C28: =IFERROR(__xludf.DUMMYFUNCTION("""COMPUTED_VALUE"""),"Kedi Ödül Maması Karışık 60 gr X 24 Adet") -> Kedi Ödül Maması Karışık 60 gr X 24 Adet | D28: =IFERROR(__xludf.DUMMYFUNCTION("""COMPUTED_VALUE"""),1019.08) -> 1019.08 | E28: =IFERROR(__xludf.DUMMYFUNCTION("""COMPUTED_VALUE"""),89.67904) -> 89.67904 | F28: =IFERROR(__xludf.DUMMYFUNCTION("""COMPUTED_VALUE"""),90.0) -> 90 | G28: =IFERROR(__xludf.DUMMYFUNCTION("""COMPUTED_VALUE"""),10.0) -> 10 | H28: =IFERROR(__xludf.DUMMYFUNCTION("""COMPUTED_VALUE"""),671.6834666666666) -> 671.68347 | I28: =IFERROR(__xludf.DUMMYFUNCTION("""COMPUTED_VALUE"""),0.659107691905117) -> 0.65910769 | J28: =IFERROR(__xludf.DUMMYFUNCTION("""COMPUTED_VALUE"""),"ÇOK KÂRLI") -> ÇOK KÂRLI | K28: =IFERROR(__xludf.DUMMYFUNCTION("""COMPUTED_VALUE"""),"Stok ve BuyBox takibini artır") -> Stok ve BuyBox takibini artır
A29: =IFERROR(__xludf.DUMMYFUNCTION("""COMPUTED_VALUE"""),3.5585509006E10) -> 35585509006 | B29: =IFERROR(__xludf.DUMMYFUNCTION("""COMPUTED_VALUE"""),"Kong") -> Kong | C29: =IFERROR(__xludf.DUMMYFUNCTION("""COMPUTED_VALUE"""),"REWARDSTİNKER KÖPEKLERİÇİN ÖDÜLMAMASIDAĞITMAOYUNCAĞI M/L") -> REWARDSTİNKER KÖPEKLERİÇİN ÖDÜLMAMASIDAĞITMAOYUNCAĞI M/L | D29: =IFERROR(__xludf.DUMMYFUNCTION("""COMPUTED_VALUE"""),2197.0) -> 2197 | E29: =IFERROR(__xludf.DUMMYFUNCTION("""COMPUTED_VALUE"""),439.4) -> 439.4 | F29: =IFERROR(__xludf.DUMMYFUNCTION("""COMPUTED_VALUE"""),86.4) -> 86.4 | G29: =IFERROR(__xludf.DUMMYFUNCTION("""COMPUTED_VALUE"""),868.32) -> 868.32 | H29: =IFERROR(__xludf.DUMMYFUNCTION("""COMPUTED_VALUE"""),639.7666666666665) -> 639.76667 | I29: =IFERROR(__xludf.DUMMYFUNCTION("""COMPUTED_VALUE"""),0.2912001213776361) -> 0.29120012 | J29: =IFERROR(__xludf.DUMMYFUNCTION("""COMPUTED_VALUE"""),"ÇOK KÂRLI") -> ÇOK KÂRLI | K29: =IFERROR(__xludf.DUMMYFUNCTION("""COMPUTED_VALUE"""),"Stok ve BuyBox takibini artır") -> Stok ve BuyBox takibini artır
A30: =IFERROR(__xludf.DUMMYFUNCTION("""COMPUTED_VALUE"""),3.5585356433E10) -> 35585356433 | B30: =IFERROR(__xludf.DUMMYFUNCTION("""COMPUTED_VALUE"""),"Kong") -> Kong | C30: =IFERROR(__xludf.DUMMYFUNCTION("""COMPUTED_VALUE"""),"EXTREMEDENTAL DİŞTEMİZLİĞİSAĞLAYANKÖPEKOYUNCAĞI ULTRASERT L") -> EXTREMEDENTAL DİŞTEMİZLİĞİSAĞLAYANKÖPEKOYUNCAĞI ULTRASERT L | D30: =IFERROR(__xludf.DUMMYFUNCTION("""COMPUTED_VALUE"""),2179.0) -> 2179 | E30: =IFERROR(__xludf.DUMMYFUNCTION("""COMPUTED_VALUE"""),435.8) -> 435.8 | F30: =IFERROR(__xludf.DUMMYFUNCTION("""COMPUTED_VALUE"""),86.4) -> 86.4 | G30: =IFERROR(__xludf.DUMMYFUNCTION("""COMPUTED_VALUE"""),860.4) -> 860.4 | H30: =IFERROR(__xludf.DUMMYFUNCTION("""COMPUTED_VALUE"""),634.5166666666667) -> 634.51667 | I30: =IFERROR(__xludf.DUMMYFUNCTION("""COMPUTED_VALUE"""),0.29119626740094845) -> 0.29119627 | J30: =IFERROR(__xludf.DUMMYFUNCTION("""COMPUTED_VALUE"""),"ÇOK KÂRLI") -> ÇOK KÂRLI | K30: =IFERROR(__xludf.DUMMYFUNCTION("""COMPUTED_VALUE"""),"Stok ve BuyBox takibini artır") -> Stok ve BuyBox takibini artır
A31: =IFERROR(__xludf.DUMMYFUNCTION("""COMPUTED_VALUE"""),"TYBT0G6C7YR9R8WA07") -> TYBT0G6C7YR9R8WA07 | B31: =IFERROR(__xludf.DUMMYFUNCTION("""COMPUTED_VALUE"""),"Royal Canin") -> Royal Canin | C31: =IFERROR(__xludf.DUMMYFUNCTION("""COMPUTED_VALUE"""),"Orta Irklar için Yavru Yaş Köpek Maması 10 x 140g") -> Orta Irklar için Yavru Yaş Köpek Maması 10 x 140g | D31: =IFERROR(__xludf.DUMMYFUNCTION("""COMPUTED_VALUE"""),999.0) -> 999 | E31: =IFERROR(__xludf.DUMMYFUNCTION("""COMPUTED_VALUE"""),124.875) -> 124.875 | F31: =IFERROR(__xludf.DUMMYFUNCTION("""COMPUTED_VALUE"""),90.0) -> 90 | G31: =IFERROR(__xludf.DUMMYFUNCTION("""COMPUTED_VALUE"""),1.0) -> 1 | H31: =IFERROR(__xludf.DUMMYFUNCTION("""COMPUTED_VALUE"""),633.2874999999999) -> 633.2875 | I31: =IFERROR(__xludf.DUMMYFUNCTION("""COMPUTED_VALUE"""),0.6339214214214214) -> 0.63392142 | J31: =IFERROR(__xludf.DUMMYFUNCTION("""COMPUTED_VALUE"""),"ÇOK KÂRLI") -> ÇOK KÂRLI | K31: =IFERROR(__xludf.DUMMYFUNCTION("""COMPUTED_VALUE"""),"Stok ve BuyBox takibini artır") -> Stok ve BuyBox takibini artır
A34: En Riskli Zarar Eden İlk 10 Ürün
A35: Barkod | B35: Marka | C35: Ürün Adı | D35: BuyBox Fiyatı | E35: Komisyon | F35: Kargo | G35: Maliyet | H35: Min. Satış Fiyatı | I35: Net Kâr | J35: Kâr Oranı | K35: Aksiyon
A36: =IFERROR(__xludf.DUMMYFUNCTION("SORTN(FILTER({'BuyBox Karlilik'!A2:G300,'BuyBox Karlilik'!R2:R300,'BuyBox Karlilik'!K2:L300,'BuyBox Karlilik'!U2:U300},'BuyBox Karlilik'!T2:T300=""ZARAR""),10,0,9,TRUE)"),3.5585494029E10) -> 35585494029 | B36: =IFERROR(__xludf.DUMMYFUNCTION("""COMPUTED_VALUE"""),"Kong") -> Kong | C36: =IFERROR(__xludf.DUMMYFUNCTION("""COMPUTED_VALUE"""),"KONGSİGNATURE STİCKÇUBUK ŞEKLİNDEKÖPEKOYUNCAĞI M") -> KONGSİGNATURE STİCKÇUBUK ŞEKLİNDEKÖPEKOYUNCAĞI M | D36: =IFERROR(__xludf.DUMMYFUNCTION("""COMPUTED_VALUE"""),880.0) -> 880 | E36: =IFERROR(__xludf.DUMMYFUNCTION("""COMPUTED_VALUE"""),176.0) -> 176 | F36: =IFERROR(__xludf.DUMMYFUNCTION("""COMPUTED_VALUE"""),86.4) -> 86.4 | G36: =IFERROR(__xludf.DUMMYFUNCTION("""COMPUTED_VALUE"""),860.4) -> 860.4 | H36: =IFERROR(__xludf.DUMMYFUNCTION("""COMPUTED_VALUE"""),1212.6184367922372) -> 1212.6184 | I36: =IFERROR(__xludf.DUMMYFUNCTION("""COMPUTED_VALUE"""),-263.32333333333327) -> -263.32333 | J36: =IFERROR(__xludf.DUMMYFUNCTION("""COMPUTED_VALUE"""),-0.29923106060606053) -> -0.29923106 | K36: =IFERROR(__xludf.DUMMYFUNCTION("""COMPUTED_VALUE"""),"Fiyat, maliyet veya kampanya kontrol et") -> Fiyat, maliyet veya kampanya kontrol et
A37: =IFERROR(__xludf.DUMMYFUNCTION("""COMPUTED_VALUE"""),9.003579008485E12) -> 9003579008485 | B37: =IFERROR(__xludf.DUMMYFUNCTION("""COMPUTED_VALUE"""),"Royal Canin") -> Royal Canin | C37: =IFERROR(__xludf.DUMMYFUNCTION("""COMPUTED_VALUE"""),"Maxi Adult Gravy Yetişkin Köpek Konservesi 10 Adet 140 Gr") -> Maxi Adult Gravy Yetişkin Köpek Konservesi 10 Adet 140 Gr | D37: =IFERROR(__xludf.DUMMYFUNCTION("""COMPUTED_VALUE"""),465.0) -> 465 | E37: =IFERROR(__xludf.DUMMYFUNCTION("""COMPUTED_VALUE"""),58.125) -> 58.125 | F37: =IFERROR(__xludf.DUMMYFUNCTION("""COMPUTED_VALUE"""),86.4) -> 86.4 | G37: =IFERROR(__xludf.DUMMYFUNCTION("""COMPUTED_VALUE"""),536.76) -> 536.76 | H37: =IFERROR(__xludf.DUMMYFUNCTION("""COMPUTED_VALUE"""),734.2497175962625) -> 734.24972 | I37: =IFERROR(__xludf.DUMMYFUNCTION("""COMPUTED_VALUE"""),-233.34999999999997) -> -233.35 | J37: =IFERROR(__xludf.DUMMYFUNCTION("""COMPUTED_VALUE"""),-0.5018279569892472) -> -0.50182796 | K37: =IFERROR(__xludf.DUMMYFUNCTION("""COMPUTED_VALUE"""),"Fiyat, maliyet veya kampanya kontrol et") -> Fiyat, maliyet veya kampanya kontrol et
A38: =IFERROR(__xludf.DUMMYFUNCTION("""COMPUTED_VALUE"""),"TY988899455015287") -> TY988899455015287 | B38: =IFERROR(__xludf.DUMMYFUNCTION("""COMPUTED_VALUE"""),"Royal Canin") -> Royal Canin | C38: =IFERROR(__xludf.DUMMYFUNCTION("""COMPUTED_VALUE"""),"Mini Starter Mother & Babydog Anne ve Yavru Köpek Maması 4kg") -> Mini Starter Mother & Babydog Anne ve Yavru Köpek Maması 4kg | D38: =IFERROR(__xludf.DUMMYFUNCTION("""COMPUTED_VALUE"""),1555.99) -> 1555.99 | E38: =IFERROR(__xludf.DUMMYFUNCTION("""COMPUTED_VALUE"""),130.70316) -> 130.70316 | F38: =IFERROR(__xludf.DUMMYFUNCTION("""COMPUTED_VALUE"""),90.0) -> 90 | G38: =IFERROR(__xludf.DUMMYFUNCTION("""COMPUTED_VALUE"""),1537.0) -> 1537 | H38: =IFERROR(__xludf.DUMMYFUNCTION("""COMPUTED_VALUE"""),1807.0393657585878) -> 1807.0394 | I38: =IFERROR(__xludf.DUMMYFUNCTION("""COMPUTED_VALUE"""),-227.86974333333336) -> -227.86974 | J38: =IFERROR(__xludf.DUMMYFUNCTION("""COMPUTED_VALUE"""),-0.14644679164604743) -> -0.14644679 | K38: =IFERROR(__xludf.DUMMYFUNCTION("""COMPUTED_VALUE"""),"Fiyat, maliyet veya kampanya kontrol et") -> Fiyat, maliyet veya kampanya kontrol et
A39: =IFERROR(__xludf.DUMMYFUNCTION("""COMPUTED_VALUE"""),"TYBUPYD47K660EFG52") -> TYBUPYD47K660EFG52 | B39: =IFERROR(__xludf.DUMMYFUNCTION("""COMPUTED_VALUE"""),"Hill's") -> Hill's | C39: =IFERROR(__xludf.DUMMYFUNCTION("""COMPUTED_VALUE"""),"Hills Sterilised Somon Kısır Kedi Maması 10 Kg") -> Hills Sterilised Somon Kısır Kedi Maması 10 Kg | D39: =IFERROR(__xludf.DUMMYFUNCTION("""COMPUTED_VALUE"""),4399.72) -> 4399.72 | E39: =IFERROR(__xludf.DUMMYFUNCTION("""COMPUTED_VALUE"""),549.965) -> 549.965 | F39: =IFERROR(__xludf.DUMMYFUNCTION("""COMPUTED_VALUE"""),90.0) -> 90 | G39: =IFERROR(__xludf.DUMMYFUNCTION("""COMPUTED_VALUE"""),3900.0) -> 3900 | H39: =IFERROR(__xludf.DUMMYFUNCTION("""COMPUTED_VALUE"""),4619.063608052459) -> 4619.0636 | I39: =IFERROR(__xludf.DUMMYFUNCTION("""COMPUTED_VALUE"""),-190.09933333333322) -> -190.09933 | J39: =IFERROR(__xludf.DUMMYFUNCTION("""COMPUTED_VALUE"""),-0.043207143484888404) -> -0.043207143 | K39: =IFERROR(__xludf.DUMMYFUNCTION("""COMPUTED_VALUE"""),"Fiyat, maliyet veya kampanya kontrol et") -> Fiyat, maliyet veya kampanya kontrol et
A40: =IFERROR(__xludf.DUMMYFUNCTION("""COMPUTED_VALUE"""),6.13033566523E11) -> 613033566523 | B40: =IFERROR(__xludf.DUMMYFUNCTION("""COMPUTED_VALUE"""),"Pro Plan") -> Pro Plan | C40: =IFERROR(__xludf.DUMMYFUNCTION("""COMPUTED_VALUE"""),"Kısırlaştırılmış Somonlu Kedi Maması 10 Kg") -> Kısırlaştırılmış Somonlu Kedi Maması 10 Kg | D40: =IFERROR(__xludf.DUMMYFUNCTION("""COMPUTED_VALUE"""),3998.0) -> 3998 | E40: =IFERROR(__xludf.DUMMYFUNCTION("""COMPUTED_VALUE"""),499.75) -> 499.75 | F40: =IFERROR(__xludf.DUMMYFUNCTION("""COMPUTED_VALUE"""),159.74) -> 159.74 | G40: =IFERROR(__xludf.DUMMYFUNCTION("""COMPUTED_VALUE"""),3475.0) -> 3475 | H40: =IFERROR(__xludf.DUMMYFUNCTION("""COMPUTED_VALUE"""),4209.148381096777) -> 4209.1484 | I40: =IFERROR(__xludf.DUMMYFUNCTION("""COMPUTED_VALUE"""),-182.99666666666644) -> -182.99667 | J40: =IFERROR(__xludf.DUMMYFUNCTION("""COMPUTED_VALUE"""),-0.04577205269301312) -> -0.045772053 | K40: =IFERROR(__xludf.DUMMYFUNCTION("""COMPUTED_VALUE"""),"Fiyat, maliyet veya kampanya kontrol et") -> Fiyat, maliyet veya kampanya kontrol et
A41: =IFERROR(__xludf.DUMMYFUNCTION("""COMPUTED_VALUE"""),7.613033566523E12) -> 7613033566523 | B41: =IFERROR(__xludf.DUMMYFUNCTION("""COMPUTED_VALUE"""),"Pro Plan") -> Pro Plan | C41: =IFERROR(__xludf.DUMMYFUNCTION("""COMPUTED_VALUE"""),"Sterilised Kısırlaştırılmış Somonlu Kedi Maması 10 KG") -> Sterilised Kısırlaştırılmış Somonlu Kedi Maması 10 KG | D41: =IFERROR(__xludf.DUMMYFUNCTION("""COMPUTED_VALUE"""),4000.0) -> 4000 | E41: =IFERROR(__xludf.DUMMYFUNCTION("""COMPUTED_VALUE"""),500.0) -> 500 | F41: =IFERROR(__xludf.DUMMYFUNCTION("""COMPUTED_VALUE"""),159.74) -> 159.74 | G41: =IFERROR(__xludf.DUMMYFUNCTION("""COMPUTED_VALUE"""),3474.24) -> 3474.24 | H41: =IFERROR(__xludf.DUMMYFUNCTION("""COMPUTED_VALUE"""),4208.271458357131) -> 4208.2715 | I41: =IFERROR(__xludf.DUMMYFUNCTION("""COMPUTED_VALUE"""),-180.5033333333329) -> -180.50333 | J41: =IFERROR(__xludf.DUMMYFUNCTION("""COMPUTED_VALUE"""),-0.045125833333333226) -> -0.045125833 | K41: =IFERROR(__xludf.DUMMYFUNCTION("""COMPUTED_VALUE"""),"Fiyat, maliyet veya kampanya kontrol et") -> Fiyat, maliyet veya kampanya kontrol et
A42: =IFERROR(__xludf.DUMMYFUNCTION("""COMPUTED_VALUE"""),9.003579308745E12) -> 9003579308745 | B42: =IFERROR(__xludf.DUMMYFUNCTION("""COMPUTED_VALUE"""),"Royal Canin") -> Royal Canin | C42: =IFERROR(__xludf.DUMMYFUNCTION("""COMPUTED_VALUE"""),"Gravy Yavru Kedi Konservesi 85 gr 12 Adet") -> Gravy Yavru Kedi Konservesi 85 gr 12 Adet | D42: =IFERROR(__xludf.DUMMYFUNCTION("""COMPUTED_VALUE"""),559.0) -> 559 | E42: =IFERROR(__xludf.DUMMYFUNCTION("""COMPUTED_VALUE"""),42.483999999999995) -> 42.484 | F42: =IFERROR(__xludf.DUMMYFUNCTION("""COMPUTED_VALUE"""),86.4) -> 86.4 | G42: =IFERROR(__xludf.DUMMYFUNCTION("""COMPUTED_VALUE"""),557.76) -> 557.76 | H42: =IFERROR(__xludf.DUMMYFUNCTION("""COMPUTED_VALUE"""),717.8919847499145) -> 717.89198 | I42: =IFERROR(__xludf.DUMMYFUNCTION("""COMPUTED_VALUE"""),-145.49233333333333) -> -145.49233 | J42: =IFERROR(__xludf.DUMMYFUNCTION("""COMPUTED_VALUE"""),-0.26027251043530114) -> -0.26027251 | K42: =IFERROR(__xludf.DUMMYFUNCTION("""COMPUTED_VALUE"""),"Fiyat, maliyet veya kampanya kontrol et") -> Fiyat, maliyet veya kampanya kontrol et
A43: =IFERROR(__xludf.DUMMYFUNCTION("""COMPUTED_VALUE"""),9.003579308738E12) -> 9003579308738 | B43: =IFERROR(__xludf.DUMMYFUNCTION("""COMPUTED_VALUE"""),"Royal Canin") -> Royal Canin | C43: =IFERROR(__xludf.DUMMYFUNCTION("""COMPUTED_VALUE"""),"Instinctive Yaş Kedi Maması 12 x 85g") -> Instinctive Yaş Kedi Maması 12 x 85g | D43: =IFERROR(__xludf.DUMMYFUNCTION("""COMPUTED_VALUE"""),527.09) -> 527.09 | E43: =IFERROR(__xludf.DUMMYFUNCTION("""COMPUTED_VALUE"""),42.1672) -> 42.1672 | F43: =IFERROR(__xludf.DUMMYFUNCTION("""COMPUTED_VALUE"""),86.4) -> 86.4 | G43: =IFERROR(__xludf.DUMMYFUNCTION("""COMPUTED_VALUE"""),504.0) -> 504 | H43: =IFERROR(__xludf.DUMMYFUNCTION("""COMPUTED_VALUE"""),662.0728840684154) -> 662.07288 | I43: =IFERROR(__xludf.DUMMYFUNCTION("""COMPUTED_VALUE"""),-123.05961666666659) -> -123.05962 | J43: =IFERROR(__xludf.DUMMYFUNCTION("""COMPUTED_VALUE"""),-0.23346983753565156) -> -0.23346984 | K43: =IFERROR(__xludf.DUMMYFUNCTION("""COMPUTED_VALUE"""),"Fiyat, maliyet veya kampanya kontrol et") -> Fiyat, maliyet veya kampanya kontrol et
A44: =IFERROR(__xludf.DUMMYFUNCTION("""COMPUTED_VALUE"""),"HBCV0000CCFV8V") -> HBCV0000CCFV8V | B44: =IFERROR(__xludf.DUMMYFUNCTION("""COMPUTED_VALUE"""),"Pro Plan") -> Pro Plan | C44: =IFERROR(__xludf.DUMMYFUNCTION("""COMPUTED_VALUE"""),"Kitten Yavru Kedi Kuru Maması 400 gr 4 Adet") -> Kitten Yavru Kedi Kuru Maması 400 gr 4 Adet | D44: =IFERROR(__xludf.DUMMYFUNCTION("""COMPUTED_VALUE"""),650.0) -> 650 | E44: =IFERROR(__xludf.DUMMYFUNCTION("""COMPUTED_VALUE"""),81.25) -> 81.25 | F44: =IFERROR(__xludf.DUMMYFUNCTION("""COMPUTED_VALUE"""),90.0) -> 90 | G44: =IFERROR(__xludf.DUMMYFUNCTION("""COMPUTED_VALUE"""),580.0) -> 580 | H44: =IFERROR(__xludf.DUMMYFUNCTION("""COMPUTED_VALUE"""),788.2958506554421) -> 788.29585 | I44: =IFERROR(__xludf.DUMMYFUNCTION("""COMPUTED_VALUE"""),-119.85666666666667) -> -119.85667 | J44: =IFERROR(__xludf.DUMMYFUNCTION("""COMPUTED_VALUE"""),-0.1843948717948718) -> -0.18439487 | K44: =IFERROR(__xludf.DUMMYFUNCTION("""COMPUTED_VALUE"""),"Fiyat, maliyet veya kampanya kontrol et") -> Fiyat, maliyet veya kampanya kontrol et
...

Sheet Uyarilar
A1: Operasyon Uyarıları
A3: Zarar Eden Ürünler
A4: Barkod | B4: Marka | C4: Ürün Adı | D4: BuyBox Fiyatı | E4: Net Kâr / Zarar | F4: Kâr Oranı % | G4: Risk | H4: Aksiyon
A5: =IFERROR(__xludf.DUMMYFUNCTION("SORTN(FILTER({'BuyBox Karlilik'!A2:D300,'BuyBox Karlilik'!K2:L300,'BuyBox Karlilik'!T2:U300},'BuyBox Karlilik'!T2:T300=""ZARAR""),20,0,5,TRUE)"),3.5585494029E10) -> 35585494029 | B5: =IFERROR(__xludf.DUMMYFUNCTION("""COMPUTED_VALUE"""),"Kong") -> Kong | C5: =IFERROR(__xludf.DUMMYFUNCTION("""COMPUTED_VALUE"""),"KONGSİGNATURE STİCKÇUBUK ŞEKLİNDEKÖPEKOYUNCAĞI M") -> KONGSİGNATURE STİCKÇUBUK ŞEKLİNDEKÖPEKOYUNCAĞI M | D5: =IFERROR(__xludf.DUMMYFUNCTION("""COMPUTED_VALUE"""),880.0) -> 880 | E5: =IFERROR(__xludf.DUMMYFUNCTION("""COMPUTED_VALUE"""),-263.32333333333327) -> -263.32333 | F5: =IFERROR(__xludf.DUMMYFUNCTION("""COMPUTED_VALUE"""),-0.29923106060606053) -> -0.29923106 | G5: =IFERROR(__xludf.DUMMYFUNCTION("""COMPUTED_VALUE"""),"ZARAR") -> ZARAR | H5: =IFERROR(__xludf.DUMMYFUNCTION("""COMPUTED_VALUE"""),"Fiyat, maliyet veya kampanya kontrol et") -> Fiyat, maliyet veya kampanya kontrol et
A6: =IFERROR(__xludf.DUMMYFUNCTION("""COMPUTED_VALUE"""),9.003579008485E12) -> 9003579008485 | B6: =IFERROR(__xludf.DUMMYFUNCTION("""COMPUTED_VALUE"""),"Royal Canin") -> Royal Canin | C6: =IFERROR(__xludf.DUMMYFUNCTION("""COMPUTED_VALUE"""),"Maxi Adult Gravy Yetişkin Köpek Konservesi 10 Adet 140 Gr") -> Maxi Adult Gravy Yetişkin Köpek Konservesi 10 Adet 140 Gr | D6: =IFERROR(__xludf.DUMMYFUNCTION("""COMPUTED_VALUE"""),465.0) -> 465 | E6: =IFERROR(__xludf.DUMMYFUNCTION("""COMPUTED_VALUE"""),-233.34999999999997) -> -233.35 | F6: =IFERROR(__xludf.DUMMYFUNCTION("""COMPUTED_VALUE"""),-0.5018279569892472) -> -0.50182796 | G6: =IFERROR(__xludf.DUMMYFUNCTION("""COMPUTED_VALUE"""),"ZARAR") -> ZARAR | H6: =IFERROR(__xludf.DUMMYFUNCTION("""COMPUTED_VALUE"""),"Fiyat, maliyet veya kampanya kontrol et") -> Fiyat, maliyet veya kampanya kontrol et
A7: =IFERROR(__xludf.DUMMYFUNCTION("""COMPUTED_VALUE"""),"TY988899455015287") -> TY988899455015287 | B7: =IFERROR(__xludf.DUMMYFUNCTION("""COMPUTED_VALUE"""),"Royal Canin") -> Royal Canin | C7: =IFERROR(__xludf.DUMMYFUNCTION("""COMPUTED_VALUE"""),"Mini Starter Mother & Babydog Anne ve Yavru Köpek Maması 4kg") -> Mini Starter Mother & Babydog Anne ve Yavru Köpek Maması 4kg | D7: =IFERROR(__xludf.DUMMYFUNCTION("""COMPUTED_VALUE"""),1555.99) -> 1555.99 | E7: =IFERROR(__xludf.DUMMYFUNCTION("""COMPUTED_VALUE"""),-227.86974333333336) -> -227.86974 | F7: =IFERROR(__xludf.DUMMYFUNCTION("""COMPUTED_VALUE"""),-0.14644679164604743) -> -0.14644679 | G7: =IFERROR(__xludf.DUMMYFUNCTION("""COMPUTED_VALUE"""),"ZARAR") -> ZARAR | H7: =IFERROR(__xludf.DUMMYFUNCTION("""COMPUTED_VALUE"""),"Fiyat, maliyet veya kampanya kontrol et") -> Fiyat, maliyet veya kampanya kontrol et
A8: =IFERROR(__xludf.DUMMYFUNCTION("""COMPUTED_VALUE"""),"TYBUPYD47K660EFG52") -> TYBUPYD47K660EFG52 | B8: =IFERROR(__xludf.DUMMYFUNCTION("""COMPUTED_VALUE"""),"Hill's") -> Hill's | C8: =IFERROR(__xludf.DUMMYFUNCTION("""COMPUTED_VALUE"""),"Hills Sterilised Somon Kısır Kedi Maması 10 Kg") -> Hills Sterilised Somon Kısır Kedi Maması 10 Kg | D8: =IFERROR(__xludf.DUMMYFUNCTION("""COMPUTED_VALUE"""),4399.72) -> 4399.72 | E8: =IFERROR(__xludf.DUMMYFUNCTION("""COMPUTED_VALUE"""),-190.09933333333322) -> -190.09933 | F8: =IFERROR(__xludf.DUMMYFUNCTION("""COMPUTED_VALUE"""),-0.043207143484888404) -> -0.043207143 | G8: =IFERROR(__xludf.DUMMYFUNCTION("""COMPUTED_VALUE"""),"ZARAR") -> ZARAR | H8: =IFERROR(__xludf.DUMMYFUNCTION("""COMPUTED_VALUE"""),"Fiyat, maliyet veya kampanya kontrol et") -> Fiyat, maliyet veya kampanya kontrol et
A9: =IFERROR(__xludf.DUMMYFUNCTION("""COMPUTED_VALUE"""),6.13033566523E11) -> 613033566523 | B9: =IFERROR(__xludf.DUMMYFUNCTION("""COMPUTED_VALUE"""),"Pro Plan") -> Pro Plan | C9: =IFERROR(__xludf.DUMMYFUNCTION("""COMPUTED_VALUE"""),"Kısırlaştırılmış Somonlu Kedi Maması 10 Kg") -> Kısırlaştırılmış Somonlu Kedi Maması 10 Kg | D9: =IFERROR(__xludf.DUMMYFUNCTION("""COMPUTED_VALUE"""),3998.0) -> 3998 | E9: =IFERROR(__xludf.DUMMYFUNCTION("""COMPUTED_VALUE"""),-182.99666666666644) -> -182.99667 | F9: =IFERROR(__xludf.DUMMYFUNCTION("""COMPUTED_VALUE"""),-0.04577205269301312) -> -0.045772053 | G9: =IFERROR(__xludf.DUMMYFUNCTION("""COMPUTED_VALUE"""),"ZARAR") -> ZARAR | H9: =IFERROR(__xludf.DUMMYFUNCTION("""COMPUTED_VALUE"""),"Fiyat, maliyet veya kampanya kontrol et") -> Fiyat, maliyet veya kampanya kontrol et
A10: =IFERROR(__xludf.DUMMYFUNCTION("""COMPUTED_VALUE"""),7.613033566523E12) -> 7613033566523 | B10: =IFERROR(__xludf.DUMMYFUNCTION("""COMPUTED_VALUE"""),"Pro Plan") -> Pro Plan | C10: =IFERROR(__xludf.DUMMYFUNCTION("""COMPUTED_VALUE"""),"Sterilised Kısırlaştırılmış Somonlu Kedi Maması 10 KG") -> Sterilised Kısırlaştırılmış Somonlu Kedi Maması 10 KG | D10: =IFERROR(__xludf.DUMMYFUNCTION("""COMPUTED_VALUE"""),4000.0) -> 4000 | E10: =IFERROR(__xludf.DUMMYFUNCTION("""COMPUTED_VALUE"""),-180.5033333333329) -> -180.50333 | F10: =IFERROR(__xludf.DUMMYFUNCTION("""COMPUTED_VALUE"""),-0.045125833333333226) -> -0.045125833 | G10: =IFERROR(__xludf.DUMMYFUNCTION("""COMPUTED_VALUE"""),"ZARAR") -> ZARAR | H10: =IFERROR(__xludf.DUMMYFUNCTION("""COMPUTED_VALUE"""),"Fiyat, maliyet veya kampanya kontrol et") -> Fiyat, maliyet veya kampanya kontrol et
A11: =IFERROR(__xludf.DUMMYFUNCTION("""COMPUTED_VALUE"""),9.003579308745E12) -> 9003579308745 | B11: =IFERROR(__xludf.DUMMYFUNCTION("""COMPUTED_VALUE"""),"Royal Canin") -> Royal Canin | C11: =IFERROR(__xludf.DUMMYFUNCTION("""COMPUTED_VALUE"""),"Gravy Yavru Kedi Konservesi 85 gr 12 Adet") -> Gravy Yavru Kedi Konservesi 85 gr 12 Adet | D11: =IFERROR(__xludf.DUMMYFUNCTION("""COMPUTED_VALUE"""),559.0) -> 559 | E11: =IFERROR(__xludf.DUMMYFUNCTION("""COMPUTED_VALUE"""),-145.49233333333333) -> -145.49233 | F11: =IFERROR(__xludf.DUMMYFUNCTION("""COMPUTED_VALUE"""),-0.26027251043530114) -> -0.26027251 | G11: =IFERROR(__xludf.DUMMYFUNCTION("""COMPUTED_VALUE"""),"ZARAR") -> ZARAR | H11: =IFERROR(__xludf.DUMMYFUNCTION("""COMPUTED_VALUE"""),"Fiyat, maliyet veya kampanya kontrol et") -> Fiyat, maliyet veya kampanya kontrol et
A12: =IFERROR(__xludf.DUMMYFUNCTION("""COMPUTED_VALUE"""),9.003579308738E12) -> 9003579308738 | B12: =IFERROR(__xludf.DUMMYFUNCTION("""COMPUTED_VALUE"""),"Royal Canin") -> Royal Canin | C12: =IFERROR(__xludf.DUMMYFUNCTION("""COMPUTED_VALUE"""),"Instinctive Yaş Kedi Maması 12 x 85g") -> Instinctive Yaş Kedi Maması 12 x 85g | D12: =IFERROR(__xludf.DUMMYFUNCTION("""COMPUTED_VALUE"""),527.09) -> 527.09 | E12: =IFERROR(__xludf.DUMMYFUNCTION("""COMPUTED_VALUE"""),-123.05961666666659) -> -123.05962 | F12: =IFERROR(__xludf.DUMMYFUNCTION("""COMPUTED_VALUE"""),-0.23346983753565156) -> -0.23346984 | G12: =IFERROR(__xludf.DUMMYFUNCTION("""COMPUTED_VALUE"""),"ZARAR") -> ZARAR | H12: =IFERROR(__xludf.DUMMYFUNCTION("""COMPUTED_VALUE"""),"Fiyat, maliyet veya kampanya kontrol et") -> Fiyat, maliyet veya kampanya kontrol et
A13: =IFERROR(__xludf.DUMMYFUNCTION("""COMPUTED_VALUE"""),"HBCV0000CCFV8V") -> HBCV0000CCFV8V | B13: =IFERROR(__xludf.DUMMYFUNCTION("""COMPUTED_VALUE"""),"Pro Plan") -> Pro Plan | C13: =IFERROR(__xludf.DUMMYFUNCTION("""COMPUTED_VALUE"""),"Kitten Yavru Kedi Kuru Maması 400 gr 4 Adet") -> Kitten Yavru Kedi Kuru Maması 400 gr 4 Adet | D13: =IFERROR(__xludf.DUMMYFUNCTION("""COMPUTED_VALUE"""),650.0) -> 650 | E13: =IFERROR(__xludf.DUMMYFUNCTION("""COMPUTED_VALUE"""),-119.85666666666667) -> -119.85667 | F13: =IFERROR(__xludf.DUMMYFUNCTION("""COMPUTED_VALUE"""),-0.1843948717948718) -> -0.18439487 | G13: =IFERROR(__xludf.DUMMYFUNCTION("""COMPUTED_VALUE"""),"ZARAR") -> ZARAR | H13: =IFERROR(__xludf.DUMMYFUNCTION("""COMPUTED_VALUE"""),"Fiyat, maliyet veya kampanya kontrol et") -> Fiyat, maliyet veya kampanya kontrol et
A14: =IFERROR(__xludf.DUMMYFUNCTION("""COMPUTED_VALUE"""),9.003579013748E12) -> 9003579013748 | B14: =IFERROR(__xludf.DUMMYFUNCTION("""COMPUTED_VALUE"""),"Royal Canin") -> Royal Canin | C14: =IFERROR(__xludf.DUMMYFUNCTION("""COMPUTED_VALUE"""),"Köpek Mama Pomeranian Köpek Konserve 12X85GR") -> Köpek Mama Pomeranian Köpek Konserve 12X85GR | D14: =IFERROR(__xludf.DUMMYFUNCTION("""COMPUTED_VALUE"""),540.0) -> 540 | E14: =IFERROR(__xludf.DUMMYFUNCTION("""COMPUTED_VALUE"""),-118.78999999999996) -> -118.79 | F14: =IFERROR(__xludf.DUMMYFUNCTION("""COMPUTED_VALUE"""),-0.21998148148148142) -> -0.21998148 | G14: =IFERROR(__xludf.DUMMYFUNCTION("""COMPUTED_VALUE"""),"ZARAR") -> ZARAR | H14: =IFERROR(__xludf.DUMMYFUNCTION("""COMPUTED_VALUE"""),"Fiyat, maliyet veya kampanya kontrol et") -> Fiyat, maliyet veya kampanya kontrol et
A15: =IFERROR(__xludf.DUMMYFUNCTION("""COMPUTED_VALUE"""),8.684207638772E12) -> 8684207638772 | B15: =IFERROR(__xludf.DUMMYFUNCTION("""COMPUTED_VALUE"""),"Supreme Cat") -> Supreme Cat | C15: =IFERROR(__xludf.DUMMYFUNCTION("""COMPUTED_VALUE"""),"Ördek & Somon Kıyılmış Konserve Kedi Yaş Maması 85 gr") -> Ördek & Somon Kıyılmış Konserve Kedi Yaş Maması 85 gr | D15: =IFERROR(__xludf.DUMMYFUNCTION("""COMPUTED_VALUE"""),594.0) -> 594 | E15: =IFERROR(__xludf.DUMMYFUNCTION("""COMPUTED_VALUE"""),-112.14999999999999) -> -112.15 | F15: =IFERROR(__xludf.DUMMYFUNCTION("""COMPUTED_VALUE"""),-0.18880471380471378) -> -0.18880471 | G15: =IFERROR(__xludf.DUMMYFUNCTION("""COMPUTED_VALUE"""),"ZARAR") -> ZARAR | H15: =IFERROR(__xludf.DUMMYFUNCTION("""COMPUTED_VALUE"""),"Fiyat, maliyet veya kampanya kontrol et") -> Fiyat, maliyet veya kampanya kontrol et
A16: =IFERROR(__xludf.DUMMYFUNCTION("""COMPUTED_VALUE"""),7.613033566387E12) -> 7613033566387 | B16: =IFERROR(__xludf.DUMMYFUNCTION("""COMPUTED_VALUE"""),"Pro Plan") -> Pro Plan | C16: =IFERROR(__xludf.DUMMYFUNCTION("""COMPUTED_VALUE"""),"Renal Plus Sterilised, Somonlu Kısırlaştırılmış Kedi Maması 1.5 Kg") -> Renal Plus Sterilised, Somonlu Kısırlaştırılmış Kedi Maması 1.5 Kg | D16: =IFERROR(__xludf.DUMMYFUNCTION("""COMPUTED_VALUE"""),781.3) -> 781.3 | E16: =IFERROR(__xludf.DUMMYFUNCTION("""COMPUTED_VALUE"""),-107.15523333333341) -> -107.15523 | F16: =IFERROR(__xludf.DUMMYFUNCTION("""COMPUTED_VALUE"""),-0.1371499210717182) -> -0.13714992 | G16: =IFERROR(__xludf.DUMMYFUNCTION("""COMPUTED_VALUE"""),"ZARAR") -> ZARAR | H16: =IFERROR(__xludf.DUMMYFUNCTION("""COMPUTED_VALUE"""),"Fiyat, maliyet veya kampanya kontrol et") -> Fiyat, maliyet veya kampanya kontrol et
A17: =IFERROR(__xludf.DUMMYFUNCTION("""COMPUTED_VALUE"""),7.613033560033E12) -> 7613033560033 | B17: =IFERROR(__xludf.DUMMYFUNCTION("""COMPUTED_VALUE"""),"Pro Plan") -> Pro Plan | C17: =IFERROR(__xludf.DUMMYFUNCTION("""COMPUTED_VALUE"""),"Sterilised Hindi-Tavuk Kısırlaştırılmış Kedi Maması 3 Kg") -> Sterilised Hindi-Tavuk Kısırlaştırılmış Kedi Maması 3 Kg | D17: =IFERROR(__xludf.DUMMYFUNCTION("""COMPUTED_VALUE"""),1299.0) -> 1299 | E17: =IFERROR(__xludf.DUMMYFUNCTION("""COMPUTED_VALUE"""),-96.92500000000008) -> -96.925 | F17: =IFERROR(__xludf.DUMMYFUNCTION("""COMPUTED_VALUE"""),-0.07461508852963825) -> -0.074615089 | G17: =IFERROR(__xludf.DUMMYFUNCTION("""COMPUTED_VALUE"""),"ZARAR") -> ZARAR | H17: =IFERROR(__xludf.DUMMYFUNCTION("""COMPUTED_VALUE"""),"Fiyat, maliyet veya kampanya kontrol et") -> Fiyat, maliyet veya kampanya kontrol et
A18: =IFERROR(__xludf.DUMMYFUNCTION("""COMPUTED_VALUE"""),5.274203597E10) -> 52742035970 | B18: =IFERROR(__xludf.DUMMYFUNCTION("""COMPUTED_VALUE"""),"Hill's") -> Hill's | C18: =IFERROR(__xludf.DUMMYFUNCTION("""COMPUTED_VALUE"""),"Hill’s SCIENCE PLAN Sterilised Ördekli Kısırlaştırılmış Kedi Maması 1,5 Kg") -> Hill’s SCIENCE PLAN Sterilised Ördekli Kısırlaştırılmış Kedi Maması 1,5 Kg | D18: =IFERROR(__xludf.DUMMYFUNCTION("""COMPUTED_VALUE"""),1070.0) -> 1070 | E18: =IFERROR(__xludf.DUMMYFUNCTION("""COMPUTED_VALUE"""),-89.61666666666666) -> -89.616667 | F18: =IFERROR(__xludf.DUMMYFUNCTION("""COMPUTED_VALUE"""),-0.08375389408099689) -> -0.083753894 | G18: =IFERROR(__xludf.DUMMYFUNCTION("""COMPUTED_VALUE"""),"ZARAR") -> ZARAR | H18: =IFERROR(__xludf.DUMMYFUNCTION("""COMPUTED_VALUE"""),"Fiyat, maliyet veya kampanya kontrol et") -> Fiyat, maliyet veya kampanya kontrol et
A19: =IFERROR(__xludf.DUMMYFUNCTION("""COMPUTED_VALUE"""),9.003579008249E12) -> 9003579008249 | B19: =IFERROR(__xludf.DUMMYFUNCTION("""COMPUTED_VALUE"""),"Royal Canin") -> Royal Canin | C19: =IFERROR(__xludf.DUMMYFUNCTION("""COMPUTED_VALUE"""),"Küçük Irklar için Yetişkin Yaş Köpek Maması 12 x 85g") -> Küçük Irklar için Yetişkin Yaş Köpek Maması 12 x 85g | D19: =IFERROR(__xludf.DUMMYFUNCTION("""COMPUTED_VALUE"""),505.0) -> 505 | E19: =IFERROR(__xludf.DUMMYFUNCTION("""COMPUTED_VALUE"""),-88.12333333333335) -> -88.123333 | F19: =IFERROR(__xludf.DUMMYFUNCTION("""COMPUTED_VALUE"""),-0.17450165016501654) -> -0.17450165 | G19: =IFERROR(__xludf.DUMMYFUNCTION("""COMPUTED_VALUE"""),"ZARAR") -> ZARAR | H19: =IFERROR(__xludf.DUMMYFUNCTION("""COMPUTED_VALUE"""),"Fiyat, maliyet veya kampanya kontrol et") -> Fiyat, maliyet veya kampanya kontrol et
A20: =IFERROR(__xludf.DUMMYFUNCTION("""COMPUTED_VALUE"""),9.003579008201E12) -> 9003579008201 | B20: =IFERROR(__xludf.DUMMYFUNCTION("""COMPUTED_VALUE"""),"Royal Canin") -> Royal Canin | C20: =IFERROR(__xludf.DUMMYFUNCTION("""COMPUTED_VALUE"""),"Küçük Irklar için Yavru Yaş Köpek Maması 12 x 85g") -> Küçük Irklar için Yavru Yaş Köpek Maması 12 x 85g | D20: =IFERROR(__xludf.DUMMYFUNCTION("""COMPUTED_VALUE"""),517.0) -> 517 | E20: =IFERROR(__xludf.DUMMYFUNCTION("""COMPUTED_VALUE"""),-80.6583333333333) -> -80.658333 | F20: =IFERROR(__xludf.DUMMYFUNCTION("""COMPUTED_VALUE"""),-0.15601225016118628) -> -0.15601225 | G20: =IFERROR(__xludf.DUMMYFUNCTION("""COMPUTED_VALUE"""),"ZARAR") -> ZARAR | H20: =IFERROR(__xludf.DUMMYFUNCTION("""COMPUTED_VALUE"""),"Fiyat, maliyet veya kampanya kontrol et") -> Fiyat, maliyet veya kampanya kontrol et
A21: =IFERROR(__xludf.DUMMYFUNCTION("""COMPUTED_VALUE"""),7.613033568558E12) -> 7613033568558 | B21: =IFERROR(__xludf.DUMMYFUNCTION("""COMPUTED_VALUE"""),"Pro Plan") -> Pro Plan | C21: =IFERROR(__xludf.DUMMYFUNCTION("""COMPUTED_VALUE"""),"Sterilised Somonlu Kısırlaştırılmış Kedi Konservesi 85 Gr") -> Sterilised Somonlu Kısırlaştırılmış Kedi Konservesi 85 Gr | D21: =IFERROR(__xludf.DUMMYFUNCTION("""COMPUTED_VALUE"""),72.0) -> 72 | E21: =IFERROR(__xludf.DUMMYFUNCTION("""COMPUTED_VALUE"""),-78.19) -> -78.19 | F21: =IFERROR(__xludf.DUMMYFUNCTION("""COMPUTED_VALUE"""),-1.0859722222222221) -> -1.0859722 | G21: =IFERROR(__xludf.DUMMYFUNCTION("""COMPUTED_VALUE"""),"ZARAR") -> ZARAR | H21: =IFERROR(__xludf.DUMMYFUNCTION("""COMPUTED_VALUE"""),"Fiyat, maliyet veya kampanya kontrol et") -> Fiyat, maliyet veya kampanya kontrol et
A22: =IFERROR(__xludf.DUMMYFUNCTION("""COMPUTED_VALUE"""),9.003579308929E12) -> 9003579308929 | B22: =IFERROR(__xludf.DUMMYFUNCTION("""COMPUTED_VALUE"""),"Royal Canin") -> Royal Canin | C22: =IFERROR(__xludf.DUMMYFUNCTION("""COMPUTED_VALUE"""),"Intense Beauty Gravy Pouch Yetişkin Kedi Konservesi 85 Gr") -> Intense Beauty Gravy Pouch Yetişkin Kedi Konservesi 85 Gr | D22: =IFERROR(__xludf.DUMMYFUNCTION("""COMPUTED_VALUE"""),76.3) -> 76.3 | E22: =IFERROR(__xludf.DUMMYFUNCTION("""COMPUTED_VALUE"""),-74.46333333333334) -> -74.463333 | F22: =IFERROR(__xludf.DUMMYFUNCTION("""COMPUTED_VALUE"""),-0.9759283529925733) -> -0.97592835 | G22: =IFERROR(__xludf.DUMMYFUNCTION("""COMPUTED_VALUE"""),"ZARAR") -> ZARAR | H22: =IFERROR(__xludf.DUMMYFUNCTION("""COMPUTED_VALUE"""),"Fiyat, maliyet veya kampanya kontrol et") -> Fiyat, maliyet veya kampanya kontrol et
A23: =IFERROR(__xludf.DUMMYFUNCTION("""COMPUTED_VALUE"""),9.003579311844E12) -> 9003579311844 | B23: =IFERROR(__xludf.DUMMYFUNCTION("""COMPUTED_VALUE"""),"Royal Canin") -> Royal Canin | C23: =IFERROR(__xludf.DUMMYFUNCTION("""COMPUTED_VALUE"""),"Sterilised Jelly Kısırlaştırılmış Yetişkin Kedi Yaş Maması 85 Gr x 12") -> Sterilised Jelly Kısırlaştırılmış Yetişkin Kedi Yaş Maması 85 Gr x 12 | D23: =IFERROR(__xludf.DUMMYFUNCTION("""COMPUTED_VALUE"""),613.0) -> 613 | E23: =IFERROR(__xludf.DUMMYFUNCTION("""COMPUTED_VALUE"""),-72.32333333333331) -> -72.323333 | F23: =IFERROR(__xludf.DUMMYFUNCTION("""COMPUTED_VALUE"""),-0.11798259923871665) -> -0.1179826 | G23: =IFERROR(__xludf.DUMMYFUNCTION("""COMPUTED_VALUE"""),"ZARAR") -> ZARAR | H23: =IFERROR(__xludf.DUMMYFUNCTION("""COMPUTED_VALUE"""),"Fiyat, maliyet veya kampanya kontrol et") -> Fiyat, maliyet veya kampanya kontrol et
A24: =IFERROR(__xludf.DUMMYFUNCTION("""COMPUTED_VALUE"""),9.003579311301E12) -> 9003579311301 | B24: =IFERROR(__xludf.DUMMYFUNCTION("""COMPUTED_VALUE"""),"Royal Canin") -> Royal Canin | C24: =IFERROR(__xludf.DUMMYFUNCTION("""COMPUTED_VALUE"""),"Sterilised Gravy Yaş Kedi Maması 85 gr") -> Sterilised Gravy Yaş Kedi Maması 85 gr | D24: =IFERROR(__xludf.DUMMYFUNCTION("""COMPUTED_VALUE"""),71.0) -> 71 | E24: =IFERROR(__xludf.DUMMYFUNCTION("""COMPUTED_VALUE"""),-72.31166666666667) -> -72.311667 | F24: =IFERROR(__xludf.DUMMYFUNCTION("""COMPUTED_VALUE"""),-1.0184741784037559) -> -1.0184742 | G24: =IFERROR(__xludf.DUMMYFUNCTION("""COMPUTED_VALUE"""),"ZARAR") -> ZARAR | H24: =IFERROR(__xludf.DUMMYFUNCTION("""COMPUTED_VALUE"""),"Fiyat, maliyet veya kampanya kontrol et") -> Fiyat, maliyet veya kampanya kontrol et
A26: Eksik Verili Ürünler
A27: Barkod | B27: Marka | C27: Ürün Adı | D27: BuyBox Fiyatı | E27: Eksik Komisyon | F27: Desi | G27: Eksik Maliyet | H27: Eksik Desi | I27: Aksiyon
A28: =IFERROR(__xludf.DUMMYFUNCTION("SORTN(FILTER({'BuyBox Karlilik'!A2:D300,'BuyBox Karlilik'!N2:Q300,'BuyBox Karlilik'!U2:U300},'BuyBox Karlilik'!T2:T300=""EKSİK VERİ""),25,0,1,TRUE)"),4.53481343543E11) -> 453481343543 | B28: =IFERROR(__xludf.DUMMYFUNCTION("""COMPUTED_VALUE"""),"Mito") -> Mito | C28: =IFERROR(__xludf.DUMMYFUNCTION("""COMPUTED_VALUE"""),"La Adult Cat Tavuklu Yetişkin Kedi Maması 15 Kg") -> La Adult Cat Tavuklu Yetişkin Kedi Maması 15 Kg | D28: =IFERROR(__xludf.DUMMYFUNCTION("""COMPUTED_VALUE"""),1700.0) -> 1700 | E28: =IFERROR(__xludf.DUMMYFUNCTION("""COMPUTED_VALUE"""),"") | F28: =IFERROR(__xludf.DUMMYFUNCTION("""COMPUTED_VALUE"""),"") | G28: =IFERROR(__xludf.DUMMYFUNCTION("""COMPUTED_VALUE"""),"Maliyet eksik") -> Maliyet eksik | H28: =IFERROR(__xludf.DUMMYFUNCTION("""COMPUTED_VALUE"""),"Desi eksik") -> Desi eksik | I28: =IFERROR(__xludf.DUMMYFUNCTION("""COMPUTED_VALUE"""),"Maliyet/desi/komisyon tamamla") -> Maliyet/desi/komisyon tamamla
A29: =IFERROR(__xludf.DUMMYFUNCTION("""COMPUTED_VALUE"""),8.40134695853E11) -> 840134695853 | B29: =IFERROR(__xludf.DUMMYFUNCTION("""COMPUTED_VALUE"""),"BARK") -> BARK | C29: =IFERROR(__xludf.DUMMYFUNCTION("""COMPUTED_VALUE"""),"Starbark Beyaz Bardak Köpek Çiğneme Oyuncak - M/L Boy (Ödül Doldurulabilir)") -> Starbark Beyaz Bardak Köpek Çiğneme Oyuncak - M/L Boy (Ödül Doldurulabilir) | D29: =IFERROR(__xludf.DUMMYFUNCTION("""COMPUTED_VALUE"""),1592.91) -> 1592.91 | E29: =IFERROR(__xludf.DUMMYFUNCTION("""COMPUTED_VALUE"""),"") | F29: =IFERROR(__xludf.DUMMYFUNCTION("""COMPUTED_VALUE"""),1.0) -> 1 | G29: =IFERROR(__xludf.DUMMYFUNCTION("""COMPUTED_VALUE"""),"Maliyet eksik") -> Maliyet eksik | H29: =IFERROR(__xludf.DUMMYFUNCTION("""COMPUTED_VALUE"""),"") | I29: =IFERROR(__xludf.DUMMYFUNCTION("""COMPUTED_VALUE"""),"Maliyet/desi/komisyon tamamla") -> Maliyet/desi/komisyon tamamla
A30: =IFERROR(__xludf.DUMMYFUNCTION("""COMPUTED_VALUE"""),8.40134695921E11) -> 840134695921 | B30: =IFERROR(__xludf.DUMMYFUNCTION("""COMPUTED_VALUE"""),"BARK") -> BARK | C30: =IFERROR(__xludf.DUMMYFUNCTION("""COMPUTED_VALUE"""),"Flingray Sesli Vatos Köpek Oyuncağı") -> Flingray Sesli Vatos Köpek Oyuncağı | D30: =IFERROR(__xludf.DUMMYFUNCTION("""COMPUTED_VALUE"""),2126.52) -> 2126.52 | E30: =IFERROR(__xludf.DUMMYFUNCTION("""COMPUTED_VALUE"""),"") | F30: =IFERROR(__xludf.DUMMYFUNCTION("""COMPUTED_VALUE"""),1.0) -> 1 | G30: =IFERROR(__xludf.DUMMYFUNCTION("""COMPUTED_VALUE"""),"Maliyet eksik") -> Maliyet eksik | H30: =IFERROR(__xludf.DUMMYFUNCTION("""COMPUTED_VALUE"""),"") | I30: =IFERROR(__xludf.DUMMYFUNCTION("""COMPUTED_VALUE"""),"Maliyet/desi/komisyon tamamla") -> Maliyet/desi/komisyon tamamla
A31: =IFERROR(__xludf.DUMMYFUNCTION("""COMPUTED_VALUE"""),8.40134695938E11) -> 840134695938 | B31: =IFERROR(__xludf.DUMMYFUNCTION("""COMPUTED_VALUE"""),"BARK") -> BARK | C31: =IFERROR(__xludf.DUMMYFUNCTION("""COMPUTED_VALUE"""),"Hambone Çiğneme Köpek Oyuncağı") -> Hambone Çiğneme Köpek Oyuncağı | D31: =IFERROR(__xludf.DUMMYFUNCTION("""COMPUTED_VALUE"""),1914.66) -> 1914.66 | E31: =IFERROR(__xludf.DUMMYFUNCTION("""COMPUTED_VALUE"""),"") | F31: =IFERROR(__xludf.DUMMYFUNCTION("""COMPUTED_VALUE"""),1.0) -> 1 | G31: =IFERROR(__xludf.DUMMYFUNCTION("""COMPUTED_VALUE"""),"Maliyet eksik") -> Maliyet eksik | H31: =IFERROR(__xludf.DUMMYFUNCTION("""COMPUTED_VALUE"""),"") | I31: =IFERROR(__xludf.DUMMYFUNCTION("""COMPUTED_VALUE"""),"Maliyet/desi/komisyon tamamla") -> Maliyet/desi/komisyon tamamla
A32: =IFERROR(__xludf.DUMMYFUNCTION("""COMPUTED_VALUE"""),8.40134695983E11) -> 840134695983 | B32: =IFERROR(__xludf.DUMMYFUNCTION("""COMPUTED_VALUE"""),"BARK") -> BARK | C32: =IFERROR(__xludf.DUMMYFUNCTION("""COMPUTED_VALUE"""),"Brtha Sesli Ejderha Köpek Oyuncağı") -> Brtha Sesli Ejderha Köpek Oyuncağı | D32: =IFERROR(__xludf.DUMMYFUNCTION("""COMPUTED_VALUE"""),1286.01) -> 1286.01 | E32: =IFERROR(__xludf.DUMMYFUNCTION("""COMPUTED_VALUE"""),"") | F32: =IFERROR(__xludf.DUMMYFUNCTION("""COMPUTED_VALUE"""),1.0) -> 1 | G32: =IFERROR(__xludf.DUMMYFUNCTION("""COMPUTED_VALUE"""),"Maliyet eksik") -> Maliyet eksik | H32: =IFERROR(__xludf.DUMMYFUNCTION("""COMPUTED_VALUE"""),"") | I32: =IFERROR(__xludf.DUMMYFUNCTION("""COMPUTED_VALUE"""),"Maliyet/desi/komisyon tamamla") -> Maliyet/desi/komisyon tamamla
A33: =IFERROR(__xludf.DUMMYFUNCTION("""COMPUTED_VALUE"""),8.4013469599E11) -> 840134695990 | B33: =IFERROR(__xludf.DUMMYFUNCTION("""COMPUTED_VALUE"""),"BARK") -> BARK | C33: =IFERROR(__xludf.DUMMYFUNCTION("""COMPUTED_VALUE"""),"Acornucopia Çiğneme Köpek Oyuncağı") -> Acornucopia Çiğneme Köpek Oyuncağı | D33: =IFERROR(__xludf.DUMMYFUNCTION("""COMPUTED_VALUE"""),1583.01) -> 1583.01 | E33: =IFERROR(__xludf.DUMMYFUNCTION("""COMPUTED_VALUE"""),"") | F33: =IFERROR(__xludf.DUMMYFUNCTION("""COMPUTED_VALUE"""),1.0) -> 1 | G33: =IFERROR(__xludf.DUMMYFUNCTION("""COMPUTED_VALUE"""),"Maliyet eksik") -> Maliyet eksik | H33: =IFERROR(__xludf.DUMMYFUNCTION("""COMPUTED_VALUE"""),"") | I33: =IFERROR(__xludf.DUMMYFUNCTION("""COMPUTED_VALUE"""),"Maliyet/desi/komisyon tamamla") -> Maliyet/desi/komisyon tamamla
A34: =IFERROR(__xludf.DUMMYFUNCTION("""COMPUTED_VALUE"""),8.40134696355E11) -> 840134696355 | B34: =IFERROR(__xludf.DUMMYFUNCTION("""COMPUTED_VALUE"""),"BARK") -> BARK | C34: =IFERROR(__xludf.DUMMYFUNCTION("""COMPUTED_VALUE"""),"Turnt Turp Köpek Oyuncağı") -> Turnt Turp Köpek Oyuncağı | D34: =IFERROR(__xludf.DUMMYFUNCTION("""COMPUTED_VALUE"""),1999.0) -> 1999 | E34: =IFERROR(__xludf.DUMMYFUNCTION("""COMPUTED_VALUE"""),"") | F34: =IFERROR(__xludf.DUMMYFUNCTION("""COMPUTED_VALUE"""),1.0) -> 1 | G34: =IFERROR(__xludf.DUMMYFUNCTION("""COMPUTED_VALUE"""),"Maliyet eksik") -> Maliyet eksik | H34: =IFERROR(__xludf.DUMMYFUNCTION("""COMPUTED_VALUE"""),"") | I34: =IFERROR(__xludf.DUMMYFUNCTION("""COMPUTED_VALUE"""),"Maliyet/desi/komisyon tamamla") -> Maliyet/desi/komisyon tamamla
A35: =IFERROR(__xludf.DUMMYFUNCTION("""COMPUTED_VALUE"""),8.40134696461E11) -> 840134696461 | B35: =IFERROR(__xludf.DUMMYFUNCTION("""COMPUTED_VALUE"""),"BARK") -> BARK | C35: =IFERROR(__xludf.DUMMYFUNCTION("""COMPUTED_VALUE"""),"Fetch Dal Köpek Oyuncağı") -> Fetch Dal Köpek Oyuncağı | D35: =IFERROR(__xludf.DUMMYFUNCTION("""COMPUTED_VALUE"""),1484.01) -> 1484.01 | E35: =IFERROR(__xludf.DUMMYFUNCTION("""COMPUTED_VALUE"""),"") | F35: =IFERROR(__xludf.DUMMYFUNCTION("""COMPUTED_VALUE"""),1.0) -> 1 | G35: =IFERROR(__xludf.DUMMYFUNCTION("""COMPUTED_VALUE"""),"Maliyet eksik") -> Maliyet eksik | H35: =IFERROR(__xludf.DUMMYFUNCTION("""COMPUTED_VALUE"""),"") | I35: =IFERROR(__xludf.DUMMYFUNCTION("""COMPUTED_VALUE"""),"Maliyet/desi/komisyon tamamla") -> Maliyet/desi/komisyon tamamla
A36: =IFERROR(__xludf.DUMMYFUNCTION("""COMPUTED_VALUE"""),8.40134696485E11) -> 840134696485 | B36: =IFERROR(__xludf.DUMMYFUNCTION("""COMPUTED_VALUE"""),"BARK") -> BARK | C36: =IFERROR(__xludf.DUMMYFUNCTION("""COMPUTED_VALUE"""),"Beaver Kunduz Köpek Oyuncağı") -> Beaver Kunduz Köpek Oyuncağı | D36: =IFERROR(__xludf.DUMMYFUNCTION("""COMPUTED_VALUE"""),1557.27) -> 1557.27 | E36: =IFERROR(__xludf.DUMMYFUNCTION("""COMPUTED_VALUE"""),"") | F36: =IFERROR(__xludf.DUMMYFUNCTION("""COMPUTED_VALUE"""),1.0) -> 1 | G36: =IFERROR(__xludf.DUMMYFUNCTION("""COMPUTED_VALUE"""),"Maliyet eksik") -> Maliyet eksik | H36: =IFERROR(__xludf.DUMMYFUNCTION("""COMPUTED_VALUE"""),"") | I36: =IFERROR(__xludf.DUMMYFUNCTION("""COMPUTED_VALUE"""),"Maliyet/desi/komisyon tamamla") -> Maliyet/desi/komisyon tamamla
A37: =IFERROR(__xludf.DUMMYFUNCTION("""COMPUTED_VALUE"""),5.060255492192E12) -> 5060255492192 | B37: =IFERROR(__xludf.DUMMYFUNCTION("""COMPUTED_VALUE"""),"Ever Clean") -> Ever Clean | C37: =IFERROR(__xludf.DUMMYFUNCTION("""COMPUTED_VALUE"""),"Less Pass(PATİLERE YAPIŞMAYAN) Kedi Kumu 10 Lt") -> Less Pass(PATİLERE YAPIŞMAYAN) Kedi Kumu 10 Lt | D37: =IFERROR(__xludf.DUMMYFUNCTION("""COMPUTED_VALUE"""),1000.0) -> 1000 | E37: =IFERROR(__xludf.DUMMYFUNCTION("""COMPUTED_VALUE"""),"") | F37: =IFERROR(__xludf.DUMMYFUNCTION("""COMPUTED_VALUE"""),2.0) -> 2 | G37: =IFERROR(__xludf.DUMMYFUNCTION("""COMPUTED_VALUE"""),"Maliyet eksik") -> Maliyet eksik | H37: =IFERROR(__xludf.DUMMYFUNCTION("""COMPUTED_VALUE"""),"") | I37: =IFERROR(__xludf.DUMMYFUNCTION("""COMPUTED_VALUE"""),"Maliyet/desi/komisyon tamamla") -> Maliyet/desi/komisyon tamamla
A38: =IFERROR(__xludf.DUMMYFUNCTION("""COMPUTED_VALUE"""),5.060255492253E12) -> 5060255492253 | B38: =IFERROR(__xludf.DUMMYFUNCTION("""COMPUTED_VALUE"""),"Ever Clean") -> Ever Clean | C38: =IFERROR(__xludf.DUMMYFUNCTION("""COMPUTED_VALUE"""),"Multiple Cat Kedi Kumu 10 Lt") -> Multiple Cat Kedi Kumu 10 Lt | D38: =IFERROR(__xludf.DUMMYFUNCTION("""COMPUTED_VALUE"""),1124.1) -> 1124.1 | E38: =IFERROR(__xludf.DUMMYFUNCTION("""COMPUTED_VALUE"""),"") | F38: =IFERROR(__xludf.DUMMYFUNCTION("""COMPUTED_VALUE"""),2.0) -> 2 | G38: =IFERROR(__xludf.DUMMYFUNCTION("""COMPUTED_VALUE"""),"Maliyet eksik") -> Maliyet eksik | H38: =IFERROR(__xludf.DUMMYFUNCTION("""COMPUTED_VALUE"""),"") | I38: =IFERROR(__xludf.DUMMYFUNCTION("""COMPUTED_VALUE"""),"Maliyet/desi/komisyon tamamla") -> Maliyet/desi/komisyon tamamla
A39: =IFERROR(__xludf.DUMMYFUNCTION("""COMPUTED_VALUE"""),5.060255492291E12) -> 5060255492291 | B39: =IFERROR(__xludf.DUMMYFUNCTION("""COMPUTED_VALUE"""),"Ever Clean") -> Ever Clean | C39: =IFERROR(__xludf.DUMMYFUNCTION("""COMPUTED_VALUE"""),"Lavender Lavanta Kokulu Ince Taneli Topaklaşan Kedi Kumu 10 L") -> Lavender Lavanta Kokulu Ince Taneli Topaklaşan Kedi Kumu 10 L | D39: =IFERROR(__xludf.DUMMYFUNCTION("""COMPUTED_VALUE"""),1048.5) -> 1048.5 | E39: =IFERROR(__xludf.DUMMYFUNCTION("""COMPUTED_VALUE"""),"") | F39: =IFERROR(__xludf.DUMMYFUNCTION("""COMPUTED_VALUE"""),2.0) -> 2 | G39: =IFERROR(__xludf.DUMMYFUNCTION("""COMPUTED_VALUE"""),"Maliyet eksik") -> Maliyet eksik | H39: =IFERROR(__xludf.DUMMYFUNCTION("""COMPUTED_VALUE"""),"") | I39: =IFERROR(__xludf.DUMMYFUNCTION("""COMPUTED_VALUE"""),"Maliyet/desi/komisyon tamamla") -> Maliyet/desi/komisyon tamamla
A40: =IFERROR(__xludf.DUMMYFUNCTION("""COMPUTED_VALUE"""),5.060412212489E12) -> 5060412212489 | B40: =IFERROR(__xludf.DUMMYFUNCTION("""COMPUTED_VALUE"""),"Ever Clean") -> Ever Clean | C40: =IFERROR(__xludf.DUMMYFUNCTION("""COMPUTED_VALUE"""),"Fast Acting 10 lt.") -> Fast Acting 10 lt. | D40: =IFERROR(__xludf.DUMMYFUNCTION("""COMPUTED_VALUE"""),1169.1) -> 1169.1 | E40: =IFERROR(__xludf.DUMMYFUNCTION("""COMPUTED_VALUE"""),"") | F40: =IFERROR(__xludf.DUMMYFUNCTION("""COMPUTED_VALUE"""),2.0) -> 2 | G40: =IFERROR(__xludf.DUMMYFUNCTION("""COMPUTED_VALUE"""),"Maliyet eksik") -> Maliyet eksik | H40: =IFERROR(__xludf.DUMMYFUNCTION("""COMPUTED_VALUE"""),"") | I40: =IFERROR(__xludf.DUMMYFUNCTION("""COMPUTED_VALUE"""),"Maliyet/desi/komisyon tamamla") -> Maliyet/desi/komisyon tamamla
A41: =IFERROR(__xludf.DUMMYFUNCTION("""COMPUTED_VALUE"""),5.060412214117E12) -> 5060412214117 | B41: =IFERROR(__xludf.DUMMYFUNCTION("""COMPUTED_VALUE"""),"Ever Clean") -> Ever Clean | C41: =IFERROR(__xludf.DUMMYFUNCTION("""COMPUTED_VALUE"""),"LitterFree Paws 10 Lt") -> LitterFree Paws 10 Lt | D41: =IFERROR(__xludf.DUMMYFUNCTION("""COMPUTED_VALUE"""),1047.6) -> 1047.6 | E41: =IFERROR(__xludf.DUMMYFUNCTION("""COMPUTED_VALUE"""),"") | F41: =IFERROR(__xludf.DUMMYFUNCTION("""COMPUTED_VALUE"""),2.0) -> 2 | G41: =IFERROR(__xludf.DUMMYFUNCTION("""COMPUTED_VALUE"""),"Maliyet eksik") -> Maliyet eksik | H41: =IFERROR(__xludf.DUMMYFUNCTION("""COMPUTED_VALUE"""),"") | I41: =IFERROR(__xludf.DUMMYFUNCTION("""COMPUTED_VALUE"""),"Maliyet/desi/komisyon tamamla") -> Maliyet/desi/komisyon tamamla
A42: =IFERROR(__xludf.DUMMYFUNCTION("""COMPUTED_VALUE"""),8.005852171054E12) -> 8005852171054 | B42: =IFERROR(__xludf.DUMMYFUNCTION("""COMPUTED_VALUE"""),"Schesir") -> Schesir | C42: =IFERROR(__xludf.DUMMYFUNCTION("""COMPUTED_VALUE"""),"Jelly Ton Balıklı ve Levrekli Pouch Kedi Konservesi 85 Gr") -> Jelly Ton Balıklı ve Levrekli Pouch Kedi Konservesi 85 Gr | D42: =IFERROR(__xludf.DUMMYFUNCTION("""COMPUTED_VALUE"""),259.0) -> 259 | E42: =IFERROR(__xludf.DUMMYFUNCTION("""COMPUTED_VALUE"""),"") | F42: =IFERROR(__xludf.DUMMYFUNCTION("""COMPUTED_VALUE"""),3.0) -> 3 | G42: =IFERROR(__xludf.DUMMYFUNCTION("""COMPUTED_VALUE"""),"Maliyet eksik") -> Maliyet eksik | H42: =IFERROR(__xludf.DUMMYFUNCTION("""COMPUTED_VALUE"""),"") | I42: =IFERROR(__xludf.DUMMYFUNCTION("""COMPUTED_VALUE"""),"Maliyet/desi/komisyon tamamla") -> Maliyet/desi/komisyon tamamla
...

Sheet Maliyet Giris
A1: Barkod | B1: Marka | C1: Ürün Adı | D1: SKU | E1: Kategori | F1: Ürün Maliyeti (KDV Dahil) | G1: Ürün Desisi | H1: Not | I1: Kontrol
A2: 7613033568558 | B2: Pro Plan | C2: Sterilised Somonlu Kısırlaştırılmış Kedi Konservesi 85 Gr | E2: Kedi Konserve Maması | F2: 41 | G2: 1 | I2: =IF($A2="","",IF(COUNTIF($A$2:$A$550,$A2)>1,"Tekrarlı barkod",""))
A3: 9003579311301 | B3: Royal Canin | C3: Sterilised Gravy Yaş Kedi Maması 85 gr | E3: Kedi Konserve Maması | F3: 41 | G3: 1 | I3: =IF($A3="","",IF(COUNTIF($A$2:$A$550,$A3)>1,"Tekrarlı barkod",""))
A4: 9003579311714 | B4: Royal Canin | C4: Jelly Kitten Instinctive Yaş Yavru Kedi Maması 85 Gr | E4: Kedi Konserve Maması | F4: 41 | G4: 1 | I4: =IF($A4="","",IF(COUNTIF($A$2:$A$550,$A4)>1,"Tekrarlı barkod",""))
A5: 9003579308929 | B5: Royal Canin | C5: Intense Beauty Gravy Pouch Yetişkin Kedi Konservesi 85 Gr | E5: Kedi Konserve Maması | F5: 41 | G5: 1 | I5: =IF($A5="","",IF(COUNTIF($A$2:$A$550,$A5)>1,"Tekrarlı barkod",""))
A6: 1172022022 | B6: Royal Canin | C6: Ageing 11+ Yaşlı Ve Ileri Yaştaki Kedi Yaş Mama 85 gr X 12 Adet Gravy Soslu | E6: Kedi Konserve Maması | F6: 490 | G6: 1 | I6: =IF($A6="","",IF(COUNTIF($A$2:$A$550,$A6)>1,"Tekrarlı barkod",""))
A7: 7613035214798 | B7: Pro Plan | C7: Adult Kuzu Etli Yetişkin Köpek Maması 3 Kg | E7: Köpek Kuru Maması | F7: 872 | G7: 3 | I7: =IF($A7="","",IF(COUNTIF($A$2:$A$550,$A7)>1,"Tekrarlı barkod",""))
A8: 7613035214774 | B8: Pro Plan | C8: Adult Kuzu Etli Yetişkin Köpek Maması 14 Kg | E8: Köpek Kuru Maması | F8: 2924 | G8: 14 | I8: =IF($A8="","",IF(COUNTIF($A$2:$A$550,$A8)>1,"Tekrarlı barkod",""))
A9: 7613035214767 | B9: Pro Plan | C9: Puppy Kuzu Etli Yavru Köpek Maması 12 Kg | E9: Köpek Kuru Maması | F9: 2985 | G9: 12 | I9: =IF($A9="","",IF(COUNTIF($A$2:$A$550,$A9)>1,"Tekrarlı barkod",""))
A10: 7613035123809 | B10: Pro Plan | C10: Proplan Puppy Somonlu Küçük Irk Yavru Köpek Maması 3 Kg | E10: Köpek Kuru Maması | F10: 928 | G10: 3 | I10: =IF($A10="","",IF(COUNTIF($A$2:$A$550,$A10)>1,"Tekrarlı barkod",""))
A11: 7613035120464 | B11: Pro Plan | C11: Optiderma Somonlu Hassas Yetişkin Köpek Maması 14 Kg | E11: Köpek Kuru Maması | F11: 2991 | G11: 14 | I11: =IF($A11="","",IF(COUNTIF($A$2:$A$550,$A11)>1,"Tekrarlı barkod",""))
A12: 7613035120389 | B12: Pro Plan | C12: Puppy Somonlu Yavru Köpek Maması 12 Kg | E12: Köpek Kuru Maması | F12: 2991 | G12: 12 | I12: =IF($A12="","",IF(COUNTIF($A$2:$A$550,$A12)>1,"Tekrarlı barkod",""))
A13: 7613035119024 | B13: Pro Plan | C13: Adult Somonlu Yetişkin Köpek Maması 16.5 Kg | E13: Köpek Kuru Maması | F13: 3325 | G13: 15 | I13: =IF($A13="","",IF(COUNTIF($A$2:$A$550,$A13)>1,"Tekrarlı barkod",""))
... A18: 110201908 | B18: Purina Pro Plan | C18: Sterilised Somonlu Kısır Kedi Maması 3kg | E18: Kedi Kuru Maması | F18: 1194 | G18: 3 | I18: =IF($A18="","",IF(COUNTIF($A$2:$A$550,$A18)>1,"Tekrarlı barkod",""))
A19: 840134695853 | B19: BARK | C19: Starbark Beyaz Bardak Köpek Çiğneme Oyuncak - M/L Boy (Ödül Doldurulabilir) | E19: Köpek Oyuncağı | G19: 1 | I19: =IF($A19="","",IF(COUNTIF($A$2:$A$550,$A19)>1,"Tekrarlı barkod",""))
A20: 840134695921 | B20: BARK | C20: Flingray Sesli Vatos Köpek Oyuncağı | E20: Köpek Oyuncağı | G20: 1 | I20: =IF($A20="","",IF(COUNTIF($A$2:$A$550,$A20)>1,"Tekrarlı barkod",""))
A21: 840134695938 | B21: BARK | C21: Hambone Çiğneme Köpek Oyuncağı | E21: Köpek Oyuncağı | G21: 1 | I21: =IF($A21="","",IF(COUNTIF($A$2:$A$550,$A21)>1,"Tekrarlı barkod",""))
A22: 840134695983 | B22: BARK | C22: Brtha Sesli Ejderha Köpek Oyuncağı | E22: Köpek Oyuncağı | G22: 1 | I22: =IF($A22="","",IF(COUNTIF($A$2:$A$550,$A22)>1,"Tekrarlı barkod",""))
A23: 840134695990 | B23: BARK | C23: Acornucopia Çiğneme Köpek Oyuncağı | E23: Köpek Oyuncağı | G23: 1 | I23: =IF($A23="","",IF(COUNTIF($A$2:$A$550,$A23)>1,"Tekrarlı barkod",""))
A24: 840134696355 | B24: BARK | C24: Turnt Turp Köpek Oyuncağı | E24: Köpek Oyuncağı | G24: 1 | I24: =IF($A24="","",IF(COUNTIF($A$2:$A$550,$A24)>1,"Tekrarlı barkod",""))
A25: 840134696461 | B25: BARK | C25: Fetch Dal Köpek Oyuncağı | E25: Köpek Oyuncağı | G25: 1 | I25: =IF($A25="","",IF(COUNTIF($A$2:$A$550,$A25)>1,"Tekrarlı barkod",""))
A26: 840134696485 | B26: BARK | C26: Beaver Kunduz Köpek Oyuncağı | E26: Köpek Oyuncağı | G26: 1 | I26: =IF($A26="","",IF(COUNTIF($A$2:$A$550,$A26)>1,"Tekrarlı barkod",""))
A27: 11111111111115115 | B27: Beaphar | C27: Duo Malt Paste Tüy Yumağı Kontrol Kedi Macunu 100 gr - 2 Adet | E27: Kedi Vitamini | G27: 0.5 | I27: =IF($A27="","",IF(COUNTIF($A$2:$A$550,$A27)>1,"Tekrarlı barkod",""))
A28: 8711231170357 | B28: Beaphar | C28: Duo Malt Paste Tüy Yumağı Kontrol Kedi Macunu 100 Gr | E28: Kedi Vitamini | G28: 0.5 | I28: =IF($A28="","",IF(COUNTIF($A$2:$A$550,$A28)>1,"Tekrarlı barkod",""))
A29: TYBWE0JQNGP76NQ209 | B29: Beaphar | C29: Duo Active Tüy Yumağı Önleyici Malt Kedi Macunu 100 gr X 3 Adet | E29: Kedi Sağlık Ürünü | G29: 1 | I29: =IF($A29="","",IF(COUNTIF($A$2:$A$550,$A29)>1,"Tekrarlı barkod",""))
A30: 210420241807 | B30: N&D | C30: ND KEDİ MAMASI TROPICAL SELECTİON KISIRLAŞTIRILMIŞ KUZULU 10 KG 1 ADET | E30: Kedi Kuru Maması | F30: 2944 | G30: 10 | I30: =IF($A30="","",IF(COUNTIF($A$2:$A$550,$A30)>1,"Tekrarlı barkod",""))
A31: 8010276042149 | B31: N&D | C31: Tropical Kuzu Etli Kısırlaştırılmış Kedi Maması 10 KG | E31: Kedi Kuru Maması | F31: 2944 | G31: 10 | I31: =IF($A31="","",IF(COUNTIF($A$2:$A$550,$A31)>1,"Tekrarlı barkod",""))
A32: 5060412212489 | B32: Ever Clean | C32: Fast Acting 10 lt. | E32: Kedi Kumu | G32: 2 | I32: =IF($A32="","",IF(COUNTIF($A$2:$A$550,$A32)>1,"Tekrarlı barkod",""))
A33: 5060255492253 | B33: Ever Clean | C33: Multiple Cat Kedi Kumu 10 Lt | E33: Kedi Kumu | G33: 2 | I33: =IF($A33="","",IF(COUNTIF($A$2:$A$550,$A33)>1,"Tekrarlı barkod",""))
A34: 5060255492291 | B34: Ever Clean | C34: Lavender Lavanta Kokulu Ince Taneli Topaklaşan Kedi Kumu 10 L | E34: Kedi Kumu | G34: 2 | I34: =IF($A34="","",IF(COUNTIF($A$2:$A$550,$A34)>1,"Tekrarlı barkod",""))
A35: TYBFX202T4NBR94F79 | B35: Ever Clean | C35: Extra Strong Scented Kedi Kumu 10 Lt | E35: Kedi Kumu | G35: 2 | I35: =IF($A35="","",IF(COUNTIF($A$2:$A$550,$A35)>1,"Tekrarlı barkod",""))
A36: AK73LD91 | B36: Ever Clean | C36: Less Trail (patilere Yapışmayan) Kedi Kumu 10 Lt X 2 Adet | E36: Kedi Kumu | G36: 2 | I36: =IF($A36="","",IF(COUNTIF($A$2:$A$550,$A36)>1,"Tekrarlı barkod",""))
A37: TYBUAJE2I9OWF7YM95 | B37: Ever Clean | C37: Litter Free Paws Patilere Yapışmayan Kedi Kumu 2 X 10 L | E37: Kedi Kumu | G37: 2 | I37: =IF($A37="","",IF(COUNTIF($A$2:$A$550,$A37)>1,"Tekrarlı barkod",""))
A38: 5060255492192 | B38: Ever Clean | C38: Less Pass(PATİLERE YAPIŞMAYAN) Kedi Kumu 10 Lt | E38: Kedi Kumu | G38: 2 | I38: =IF($A38="","",IF(COUNTIF($A$2:$A$550,$A38)>1,"Tekrarlı barkod",""))
A39: 5060255492161 | B39: Ever Clean | C39: Extra Strength Scented Koku Engelleyici Doğal Kedi Kumu 10 Lt | E39: Kedi Kumu | F39: 800 | G39: 2 | I39: =IF($A39="","",IF(COUNTIF($A$2:$A$550,$A39)>1,"Tekrarlı barkod",""))
A40: 5060412214117 | B40: Ever Clean | C40: LitterFree Paws 10 Lt | E40: Kedi Kumu | G40: 2 | I40: =IF($A40="","",IF(COUNTIF($A$2:$A$550,$A40)>1,"Tekrarlı barkod",""))
A41: 8410650173535 | B41: Advance | C41: Sensitive Kuzu Etli Hassas Yetişkin Köpek Maması 12 Kg | E41: Köpek Kuru Maması | F41: 3034 | G41: 10 | I41: =IF($A41="","",IF(COUNTIF($A$2:$A$550,$A41)>1,"Tekrarlı barkod",""))
A42: 8410650167886 | B42: Advance | C42: Kedi Yetişkin Kısır Somonlu 1.5 Kg | E42: Kedi Kuru Maması | F42: 715 | G42: 3 | I42: =IF($A42="","",IF(COUNTIF($A$2:$A$550,$A42)>1,"Tekrarlı barkod",""))
A43: 8410650239156 | B43: Advance | C43: Cat Sterilized Hairball Hindili Kısır Kedi Maması 3 Kg | E43: Kedi Kuru Maması | F43: 1260 | G43: 3 | I43: =IF($A43="","",IF(COUNTIF($A$2:$A$550,$A43)>1,"Tekrarlı barkod",""))
A44: 8410650151656 | B44: Advance | C44: Cat Adult Salmon Sensıtıve 3 Kg | E44: Kedi Kuru Maması | F44: 1228 | G44: 3 | I44: =IF($A44="","",IF(COUNTIF($A$2:$A$550,$A44)>1,"Tekrarlı barkod",""))
...

Sheet Maliyetler
A1: Barkod | B1: Marka | C1: Ürün Adı | D1: SKU | E1: Kategori | F1: Satış Fiyatı | G1: BuyBox Fiyatı | H1: Stok | I1: Onay Durumu | J1: Ürün Maliyeti (KDV Dahil) | K1: Ürün Desisi
